<?xml version="1.0" ?>
<!-- =================================================================================== -->
<!-- |    This document was autogenerated by xacro from model.xacro                    | -->
<!-- |    EDITING THIS FILE BY HAND IS NOT RECOMMENDED                                 | -->
<!-- =================================================================================== -->
<robot name="primal_human">
  <link name="world"/>
  <link name="AnkleLeft_link">
    <visual>
      <geometry>
        <mesh filename="package://human_model/urdf/female/meshes/.dae" scale=""/>
      </geometry>
    </visual>
  </link>
  <joint name="world_to_AnkleLeft" type="floating">
    <parent link="world"/>
    <child link="AnkleLeft_link"/>
  </joint>
  <link name="AnkleRight_link">
    <visual>
      <geometry>
        <mesh filename="package://human_model/urdf/female/meshes/.dae" scale=""/>
      </geometry>
    </visual>
  </link>
  <joint name="world_to_AnkleRight" type="floating">
    <parent link="world"/>
    <child link="AnkleRight_link"/>
  </joint>
  <link name="ElbowLeft_link">
    <visual>
      <geometry>
        <mesh filename="package://human_model/urdf/female/meshes/.dae" scale=""/>
      </geometry>
    </visual>
  </link>
  <joint name="world_to_ElbowLeft" type="floating">
    <parent link="world"/>
    <child link="ElbowLeft_link"/>
  </joint>
  <link name="ElbowRight_link">
    <visual>
      <geometry>
        <mesh filename="package://human_model/urdf/female/meshes/.dae" scale=""/>
      </geometry>
    </visual>
  </link>
  <joint name="world_to_ElbowRight" type="floating">
    <parent link="world"/>
    <child link="ElbowRight_link"/>
  </joint>
  <link name="FootLeft_link">
    <visual>
      <geometry>
        <mesh filename="package://human_model/urdf/female/meshes/.dae" scale=""/>
      </geometry>
    </visual>
  </link>
  <joint name="world_to_FootLeft" type="floating">
    <parent link="world"/>
    <child link="FootLeft_link"/>
  </joint>
  <link name="FootRight_link">
    <visual>
      <geometry>
        <mesh filename="package://human_model/urdf/female/meshes/.dae" scale=""/>
      </geometry>
    </visual>
  </link>
  <joint name="world_to_FootRight" type="floating">
    <parent link="world"/>
    <child link="FootRight_link"/>
  </joint>
  <link name="HandLeft_link">
    <visual>
      <geometry>
        <mesh filename="package://human_model/urdf/female/meshes/.dae" scale=""/>
      </geometry>
    </visual>
  </link>
  <joint name="world_to_HandLeft" type="floating">
    <parent link="world"/>
    <child link="HandLeft_link"/>
  </joint>
  <link name="HandRight_link">
    <visual>
      <geometry>
        <mesh filename="package://human_model/urdf/female/meshes/.dae" scale=""/>
      </geometry>
    </visual>
  </link>
  <joint name="world_to_HandRight" type="floating">
    <parent link="world"/>
    <child link="HandRight_link"/>
  </joint>
  <link name="HandTipLeft_link">
    <visual>
      <geometry>
        <mesh filename="package://human_model/urdf/female/meshes/.dae" scale=""/>
      </geometry>
    </visual>
  </link>
  <joint name="world_to_HandTipLeft" type="floating">
    <parent link="world"/>
    <child link="HandTipLeft_link"/>
  </joint>
  <link name="HandTipRight_link">
    <visual>
      <geometry>
        <mesh filename="package://human_model/urdf/female/meshes/.dae" scale=""/>
      </geometry>
    </visual>
  </link>
  <joint name="world_to_HandTipRight" type="floating">
    <parent link="world"/>
    <child link="HandTipRight_link"/>
  </joint>
  <link name="Head_link">
    <visual>
      <geometry>
        <mesh filename="package://human_model/urdf/female/meshes/.dae" scale=""/>
      </geometry>
    </visual>
  </link>
  <joint name="world_to_Head" type="floating">
    <parent link="world"/>
    <child link="Head_link"/>
  </joint>
  <link name="HipLeft_link">
    <visual>
      <geometry>
        <mesh filename="package://human_model/urdf/female/meshes/.dae" scale=""/>
      </geometry>
    </visual>
  </link>
  <joint name="world_to_HipLeft" type="floating">
    <parent link="world"/>
    <child link="HipLeft_link"/>
  </joint>
  <link name="HipRight_link">
    <visual>
      <geometry>
        <mesh filename="package://human_model/urdf/female/meshes/.dae" scale=""/>
      </geometry>
    </visual>
  </link>
  <joint name="world_to_HipRight" type="floating">
    <parent link="world"/>
    <child link="HipRight_link"/>
  </joint>
  <link name="KneeLeft_link">
    <visual>
      <geometry>
        <mesh filename="package://human_model/urdf/female/meshes/.dae" scale=""/>
      </geometry>
    </visual>
  </link>
  <joint name="world_to_KneeLeft" type="floating">
    <parent link="world"/>
    <child link="KneeLeft_link"/>
  </joint>
  <link name="KneeRight_link">
    <visual>
      <geometry>
        <mesh filename="package://human_model/urdf/female/meshes/.dae" scale=""/>
      </geometry>
    </visual>
  </link>
  <joint name="world_to_KneeRight" type="floating">
    <parent link="world"/>
    <child link="KneeRight_link"/>
  </joint>
  <link name="Neck_link">
    <visual>
      <geometry>
        <mesh filename="package://human_model/urdf/female/meshes/.dae" scale=""/>
      </geometry>
    </visual>
  </link>
  <joint name="world_to_Neck" type="floating">
    <parent link="world"/>
    <child link="Neck_link"/>
  </joint>
  <link name="ShoulderLeft_link">
    <visual>
      <geometry>
        <mesh filename="package://human_model/urdf/female/meshes/.dae" scale=""/>
      </geometry>
    </visual>
  </link>
  <joint name="world_to_ShoulderLeft" type="floating">
    <parent link="world"/>
    <child link="ShoulderLeft_link"/>
  </joint>
  <link name="ShoulderRight_link">
    <visual>
      <geometry>
        <mesh filename="package://human_model/urdf/female/meshes/.dae" scale=""/>
      </geometry>
    </visual>
  </link>
  <joint name="world_to_ShoulderRight" type="floating">
    <parent link="world"/>
    <child link="ShoulderRight_link"/>
  </joint>
  <link name="SpineBase_link">
    <visual>
      <geometry>
        <mesh filename="package://human_model/urdf/female/meshes/.dae" scale=""/>
      </geometry>
    </visual>
  </link>
  <joint name="world_to_SpineBase" type="floating">
    <parent link="world"/>
    <child link="SpineBase_link"/>
  </joint>
  <link name="SpineMid_link">
    <visual>
      <geometry>
        <mesh filename="package://human_model/urdf/female/meshes/.dae" scale=""/>
      </geometry>
    </visual>
  </link>
  <joint name="world_to_SpineMid" type="floating">
    <parent link="world"/>
    <child link="SpineMid_link"/>
  </joint>
  <link name="SpineShoulder_link">
    <visual>
      <geometry>
        <mesh filename="package://human_model/urdf/female/meshes/.dae" scale=""/>
      </geometry>
    </visual>
  </link>
  <joint name="world_to_SpineShoulder" type="floating">
    <parent link="world"/>
    <child link="SpineShoulder_link"/>
  </joint>
  <link name="ThumbLeft_link">
    <visual>
      <geometry>
        <mesh filename="package://human_model/urdf/female/meshes/.dae" scale=""/>
      </geometry>
    </visual>
  </link>
  <joint name="world_to_ThumbLeft" type="floating">
    <parent link="world"/>
    <child link="ThumbLeft_link"/>
  </joint>
  <link name="ThumbRight_link">
    <visual>
      <geometry>
        <mesh filename="package://human_model/urdf/female/meshes/.dae" scale=""/>
      </geometry>
    </visual>
  </link>
  <joint name="world_to_ThumbRight" type="floating">
    <parent link="world"/>
    <child link="ThumbRight_link"/>
  </joint>
  <link name="WristLeft_link">
    <visual>
      <geometry>
        <mesh filename="package://human_model/urdf/female/meshes/.dae" scale=""/>
      </geometry>
    </visual>
  </link>
  <joint name="world_to_WristLeft" type="floating">
    <parent link="world"/>
    <child link="WristLeft_link"/>
  </joint>
  <link name="WristRight_link">
    <visual>
      <geometry>
        <mesh filename="package://human_model/urdf/female/meshes/.dae" scale=""/>
      </geometry>
    </visual>
  </link>
  <joint name="world_to_WristRight" type="floating">
    <parent link="world"/>
    <child link="WristRight_link"/>
  </joint>
  <link name="ShoulderLeft_ElbowLeft">
    <visual>
      <geometry>
        <mesh filename="package://human_model/urdf/female/meshes/ArmUpper.dae" scale="1 1 1"/>
      </geometry>
    </visual>
  </link>
  <joint name="ShoulderLeft_ElbowLeft_joint" type="fixed">
    <parent link="world"/>
    <child link="ShoulderLeft_ElbowLeft"/>
  </joint>
  <link name="ShoulderRight_ElbowRight">
    <visual>
      <geometry>
        <mesh filename="package://human_model/urdf/female/meshes/ArmUpper.dae" scale="1 -1 1"/>
      </geometry>
    </visual>
  </link>
  <joint name="ShoulderRight_ElbowRight_joint" type="fixed">
    <parent link="world"/>
    <child link="ShoulderRight_ElbowRight"/>
  </joint>
  <link name="ElbowLeft_WristLeft">
    <visual>
      <geometry>
        <mesh filename="package://human_model/urdf/female/meshes/ArmLower.dae" scale="1 1 1"/>
      </geometry>
    </visual>
  </link>
  <joint name="ElbowLeft_WristLeft_joint" type="fixed">
    <parent link="world"/>
    <child link="ElbowLeft_WristLeft"/>
  </joint>
  <link name="ElbowRight_WristRight">
    <visual>
      <geometry>
        <mesh filename="package://human_model/urdf/female/meshes/ArmLower.dae" scale="1 -1 1"/>
      </geometry>
    </visual>
  </link>
  <joint name="ElbowRight_WristRight_joint" type="fixed">
    <parent link="world"/>
    <child link="ElbowRight_WristRight"/>
  </joint>
  <link name="SpineShoulder_ShoulderLeft">
    <visual>
      <geometry>
        <mesh filename="package://human_model/urdf/female/meshes/Shoulder.dae" scale="1 1 1"/>
      </geometry>
    </visual>
  </link>
  <joint name="SpineShoulder_ShoulderLeft_joint" type="fixed">
    <parent link="world"/>
    <child link="SpineShoulder_ShoulderLeft"/>
  </joint>
  <link name="SpineShoulder_ShoulderRight">
    <visual>
      <geometry>
        <mesh filename="package://human_model/urdf/female/meshes/Shoulder.dae" scale="1 -1 1"/>
      </geometry>
    </visual>
  </link>
  <joint name="SpineShoulder_ShoulderRight_joint" type="fixed">
    <parent link="world"/>
    <child link="SpineShoulder_ShoulderRight"/>
  </joint>
  <link name="Neck_Head">
    <visual>
      <geometry>
        <mesh filename="package://human_model/urdf/female/meshes/Head.dae" scale="1 1 1"/>
      </geometry>
    </visual>
  </link>
  <joint name="Neck_Head_joint" type="fixed">
    <parent link="world"/>
    <child link="Neck_Head"/>
  </joint>
  <link name="SpineMid_SpineShoulder">
    <visual>
      <geometry>
        <mesh filename="package://human_model/urdf/female/meshes/TorsoUpper.dae" scale="1 1 1"/>
      </geometry>
    </visual>
  </link>
  <joint name="SpineMid_SpineShoulder_joint" type="fixed">
    <parent link="world"/>
    <child link="SpineMid_SpineShoulder"/>
  </joint>
  <link name="SpineMid_SpineBase">
    <visual>
      <geometry>
        <mesh filename="package://human_model/urdf/female/meshes/TorsoLower.dae" scale="1 1 1"/>
      </geometry>
    </visual>
  </link>
  <joint name="SpineMid_SpineBase_joint" type="fixed">
    <parent link="world"/>
    <child link="SpineMid_SpineBase"/>
  </joint>
  <link name="HipLeft_KneeLeft">
    <visual>
      <geometry>
        <mesh filename="package://human_model/urdf/female/meshes/LegUpper.dae" scale="1 1 1"/>
      </geometry>
    </visual>
  </link>
  <joint name="HipLeft_KneeLeft_joint" type="fixed">
    <parent link="world"/>
    <child link="HipLeft_KneeLeft"/>
  </joint>
  <link name="HipRight_KneeRight">
    <visual>
      <geometry>
        <mesh filename="package://human_model/urdf/female/meshes/LegUpper.dae" scale="1 -1 1"/>
      </geometry>
    </visual>
  </link>
  <joint name="HipRight_KneeRight_joint" type="fixed">
    <parent link="world"/>
    <child link="HipRight_KneeRight"/>
  </joint>
  <link name="KneeLeft_AnkleLeft">
    <visual>
      <geometry>
        <mesh filename="package://human_model/urdf/female/meshes/LegLower.dae" scale="1 1 1"/>
      </geometry>
    </visual>
  </link>
  <joint name="KneeLeft_AnkleLeft_joint" type="fixed">
    <parent link="world"/>
    <child link="KneeLeft_AnkleLeft"/>
  </joint>
  <link name="KneeRight_AnkleRight">
    <visual>
      <geometry>
        <mesh filename="package://human_model/urdf/female/meshes/LegLower.dae" scale="1 -1 1"/>
      </geometry>
    </visual>
  </link>
  <joint name="KneeRight_AnkleRight_joint" type="fixed">
    <parent link="world"/>
    <child link="KneeRight_AnkleRight"/>
  </joint>
  <link name="HandLeft_HandTipLeft">
    <visual>
      <geometry>
        <mesh filename="package://human_model/urdf/female/meshes/.dae" scale="0 0 0"/>
      </geometry>
    </visual>
  </link>
  <joint name="HandLeft_HandTipLeft_joint" type="fixed">
    <parent link="world"/>
    <child link="HandLeft_HandTipLeft"/>
  </joint>
  <link name="HandRight_HandTipRight">
    <visual>
      <geometry>
        <mesh filename="package://human_model/urdf/female/meshes/.dae" scale="0 0 0"/>
      </geometry>
    </visual>
  </link>
  <joint name="HandRight_HandTipRight_joint" type="fixed">
    <parent link="world"/>
    <child link="HandRight_HandTipRight"/>
  </joint>
  <link name="WristLeft_HandLeft">
    <visual>
      <geometry>
        <mesh filename="package://human_model/urdf/female/meshes/Hand.dae" scale="1 1 1"/>
      </geometry>
    </visual>
  </link>
  <joint name="WristLeft_HandLeft_joint" type="fixed">
    <parent link="world"/>
    <child link="WristLeft_HandLeft"/>
  </joint>
  <link name="WristRight_HandRight">
    <visual>
      <geometry>
        <mesh filename="package://human_model/urdf/female/meshes/Hand.dae" scale="1 -1 1"/>
      </geometry>
    </visual>
  </link>
  <joint name="WristRight_HandRight_joint" type="fixed">
    <parent link="world"/>
    <child link="WristRight_HandRight"/>
  </joint>
  <link name="HandLeft_ThumbLeft">
    <visual>
      <geometry>
        <mesh filename="package://human_model/urdf/female/meshes/.dae" scale="0 0 0"/>
      </geometry>
    </visual>
  </link>
  <joint name="HandLeft_ThumbLeft_joint" type="fixed">
    <parent link="world"/>
    <child link="HandLeft_ThumbLeft"/>
  </joint>
  <link name="HandRight_ThumbRight">
    <visual>
      <geometry>
        <mesh filename="package://human_model/urdf/female/meshes/.dae" scale="0 0 0"/>
      </geometry>
    </visual>
  </link>
  <joint name="HandRight_ThumbRight_joint" type="fixed">
    <parent link="world"/>
    <child link="HandRight_ThumbRight"/>
  </joint>
</robot>

